... logging to /home/pedro/.ros/log/rostest-noetic-964176.log
[ROSUNIT] Outputting test results to /home/pedro/.ros/test_results/fcsmap_fcs_suite/rostest-launch_fcsmap-3300-3399.xml
[Testcase: testt3300] ... FAILURE!
FAILURE: Package [fcsmap_fcs_suite_t3300] for test node [fcsmap_fcs_suite_t3300/node] does not exist
  File "/usr/lib/python3.8/unittest/case.py", line 60, in testPartExecutor
    yield
  File "/usr/lib/python3.8/unittest/case.py", line 676, in run
    self._callTestMethod(testMethod)
  File "/usr/lib/python3.8/unittest/case.py", line 633, in _callTestMethod
    method()
  File "/opt/ros/noetic/lib/python3/dist-packages/rostest/runner.py", line 93, in fn
    self.fail(message)
  File "/usr/lib/python3.8/unittest/case.py", line 753, in fail
    raise self.failureException(msg)
--------------------------------------------------------------------------------
[Testcase: testt3301] ... FAILURE!
FAILURE: Package [fcsmap_fcs_suite_t3301] for test node [fcsmap_fcs_suite_t3301/node] does not exist
  File "/usr/lib/python3.8/unittest/case.py", line 60, in testPartExecutor
    yield
  File "/usr/lib/python3.8/unittest/case.py", line 676, in run
    self._callTestMethod(testMethod)
  File "/usr/lib/python3.8/unittest/case.py", line 633, in _callTestMethod
    method()
  File "/opt/ros/noetic/lib/python3/dist-packages/rostest/runner.py", line 93, in fn
    self.fail(message)
  File "/usr/lib/python3.8/unittest/case.py", line 753, in fail
    raise self.failureException(msg)
--------------------------------------------------------------------------------
[Testcase: testt3302] ... FAILURE!
FAILURE: Package [fcsmap_fcs_suite_t3302] for test node [fcsmap_fcs_suite_t3302/node] does not exist
  File "/usr/lib/python3.8/unittest/case.py", line 60, in testPartExecutor
    yield
  File "/usr/lib/python3.8/unittest/case.py", line 676, in run
    self._callTestMethod(testMethod)
  File "/usr/lib/python3.8/unittest/case.py", line 633, in _callTestMethod
    method()
  File "/opt/ros/noetic/lib/python3/dist-packages/rostest/runner.py", line 93, in fn
    self.fail(message)
  File "/usr/lib/python3.8/unittest/case.py", line 753, in fail
    raise self.failureException(msg)
--------------------------------------------------------------------------------
[Testcase: testt3303] ... FAILURE!
FAILURE: Package [fcsmap_fcs_suite_t3303] for test node [fcsmap_fcs_suite_t3303/node] does not exist
  File "/usr/lib/python3.8/unittest/case.py", line 60, in testPartExecutor
    yield
  File "/usr/lib/python3.8/unittest/case.py", line 676, in run
    self._callTestMethod(testMethod)
  File "/usr/lib/python3.8/unittest/case.py", line 633, in _callTestMethod
    method()
  File "/opt/ros/noetic/lib/python3/dist-packages/rostest/runner.py", line 93, in fn
    self.fail(message)
  File "/usr/lib/python3.8/unittest/case.py", line 753, in fail
    raise self.failureException(msg)
--------------------------------------------------------------------------------
[Testcase: testt3304] ... FAILURE!
FAILURE: Package [fcsmap_fcs_suite_t3304] for test node [fcsmap_fcs_suite_t3304/node] does not exist
  File "/usr/lib/python3.8/unittest/case.py", line 60, in testPartExecutor
    yield
  File "/usr/lib/python3.8/unittest/case.py", line 676, in run
    self._callTestMethod(testMethod)
  File "/usr/lib/python3.8/unittest/case.py", line 633, in _callTestMethod
    method()
  File "/opt/ros/noetic/lib/python3/dist-packages/rostest/runner.py", line 93, in fn
    self.fail(message)
  File "/usr/lib/python3.8/unittest/case.py", line 753, in fail
    raise self.failureException(msg)
--------------------------------------------------------------------------------
[Testcase: testt3305] ... FAILURE!
FAILURE: Package [fcsmap_fcs_suite_t3305] for test node [fcsmap_fcs_suite_t3305/node] does not exist
  File "/usr/lib/python3.8/unittest/case.py", line 60, in testPartExecutor
    yield
  File "/usr/lib/python3.8/unittest/case.py", line 676, in run
    self._callTestMethod(testMethod)
  File "/usr/lib/python3.8/unittest/case.py", line 633, in _callTestMethod
    method()
  File "/opt/ros/noetic/lib/python3/dist-packages/rostest/runner.py", line 93, in fn
    self.fail(message)
  File "/usr/lib/python3.8/unittest/case.py", line 753, in fail
    raise self.failureException(msg)
--------------------------------------------------------------------------------
[Testcase: testt3306] ... FAILURE!
FAILURE: Package [fcsmap_fcs_suite_t3306] for test node [fcsmap_fcs_suite_t3306/node] does not exist
  File "/usr/lib/python3.8/unittest/case.py", line 60, in testPartExecutor
    yield
  File "/usr/lib/python3.8/unittest/case.py", line 676, in run
    self._callTestMethod(testMethod)
  File "/usr/lib/python3.8/unittest/case.py", line 633, in _callTestMethod
    method()
  File "/opt/ros/noetic/lib/python3/dist-packages/rostest/runner.py", line 93, in fn
    self.fail(message)
  File "/usr/lib/python3.8/unittest/case.py", line 753, in fail
    raise self.failureException(msg)
--------------------------------------------------------------------------------
[Testcase: testt3307] ... FAILURE!
FAILURE: Package [fcsmap_fcs_suite_t3307] for test node [fcsmap_fcs_suite_t3307/node] does not exist
  File "/usr/lib/python3.8/unittest/case.py", line 60, in testPartExecutor
    yield
  File "/usr/lib/python3.8/unittest/case.py", line 676, in run
    self._callTestMethod(testMethod)
  File "/usr/lib/python3.8/unittest/case.py", line 633, in _callTestMethod
    method()
  File "/opt/ros/noetic/lib/python3/dist-packages/rostest/runner.py", line 93, in fn
    self.fail(message)
  File "/usr/lib/python3.8/unittest/case.py", line 753, in fail
    raise self.failureException(msg)
--------------------------------------------------------------------------------
[Testcase: testt3308] ... FAILURE!
FAILURE: Package [fcsmap_fcs_suite_t3308] for test node [fcsmap_fcs_suite_t3308/node] does not exist
  File "/usr/lib/python3.8/unittest/case.py", line 60, in testPartExecutor
    yield
  File "/usr/lib/python3.8/unittest/case.py", line 676, in run
    self._callTestMethod(testMethod)
  File "/usr/lib/python3.8/unittest/case.py", line 633, in _callTestMethod
    method()
  File "/opt/ros/noetic/lib/python3/dist-packages/rostest/runner.py", line 93, in fn
    self.fail(message)
  File "/usr/lib/python3.8/unittest/case.py", line 753, in fail
    raise self.failureException(msg)
--------------------------------------------------------------------------------
[Testcase: testt3309] ... FAILURE!
FAILURE: Package [fcsmap_fcs_suite_t3309] for test node [fcsmap_fcs_suite_t3309/node] does not exist
  File "/usr/lib/python3.8/unittest/case.py", line 60, in testPartExecutor
    yield
  File "/usr/lib/python3.8/unittest/case.py", line 676, in run
    self._callTestMethod(testMethod)
  File "/usr/lib/python3.8/unittest/case.py", line 633, in _callTestMethod
    method()
  File "/opt/ros/noetic/lib/python3/dist-packages/rostest/runner.py", line 93, in fn
    self.fail(message)
  File "/usr/lib/python3.8/unittest/case.py", line 753, in fail
    raise self.failureException(msg)
--------------------------------------------------------------------------------
[Testcase: testt3310] ... FAILURE!
FAILURE: Package [fcsmap_fcs_suite_t3310] for test node [fcsmap_fcs_suite_t3310/node] does not exist
  File "/usr/lib/python3.8/unittest/case.py", line 60, in testPartExecutor
    yield
  File "/usr/lib/python3.8/unittest/case.py", line 676, in run
    self._callTestMethod(testMethod)
  File "/usr/lib/python3.8/unittest/case.py", line 633, in _callTestMethod
    method()
  File "/opt/ros/noetic/lib/python3/dist-packages/rostest/runner.py", line 93, in fn
    self.fail(message)
  File "/usr/lib/python3.8/unittest/case.py", line 753, in fail
    raise self.failureException(msg)
--------------------------------------------------------------------------------
[Testcase: testt3311] ... FAILURE!
FAILURE: Package [fcsmap_fcs_suite_t3311] for test node [fcsmap_fcs_suite_t3311/node] does not exist
  File "/usr/lib/python3.8/unittest/case.py", line 60, in testPartExecutor
    yield
  File "/usr/lib/python3.8/unittest/case.py", line 676, in run
    self._callTestMethod(testMethod)
  File "/usr/lib/python3.8/unittest/case.py", line 633, in _callTestMethod
    method()
  File "/opt/ros/noetic/lib/python3/dist-packages/rostest/runner.py", line 93, in fn
    self.fail(message)
  File "/usr/lib/python3.8/unittest/case.py", line 753, in fail
    raise self.failureException(msg)
--------------------------------------------------------------------------------
[Testcase: testt3312] ... FAILURE!
FAILURE: Package [fcsmap_fcs_suite_t3312] for test node [fcsmap_fcs_suite_t3312/node] does not exist
  File "/usr/lib/python3.8/unittest/case.py", line 60, in testPartExecutor
    yield
  File "/usr/lib/python3.8/unittest/case.py", line 676, in run
    self._callTestMethod(testMethod)
  File "/usr/lib/python3.8/unittest/case.py", line 633, in _callTestMethod
    method()
  File "/opt/ros/noetic/lib/python3/dist-packages/rostest/runner.py", line 93, in fn
    self.fail(message)
  File "/usr/lib/python3.8/unittest/case.py", line 753, in fail
    raise self.failureException(msg)
--------------------------------------------------------------------------------
[Testcase: testt3313] ... FAILURE!
FAILURE: Package [fcsmap_fcs_suite_t3313] for test node [fcsmap_fcs_suite_t3313/node] does not exist
  File "/usr/lib/python3.8/unittest/case.py", line 60, in testPartExecutor
    yield
  File "/usr/lib/python3.8/unittest/case.py", line 676, in run
    self._callTestMethod(testMethod)
  File "/usr/lib/python3.8/unittest/case.py", line 633, in _callTestMethod
    method()
  File "/opt/ros/noetic/lib/python3/dist-packages/rostest/runner.py", line 93, in fn
    self.fail(message)
  File "/usr/lib/python3.8/unittest/case.py", line 753, in fail
    raise self.failureException(msg)
--------------------------------------------------------------------------------
[Testcase: testt3324] ... FAILURE!
FAILURE: Package [fcsmap_fcs_suite_t3324] for test node [fcsmap_fcs_suite_t3324/node] does not exist
  File "/usr/lib/python3.8/unittest/case.py", line 60, in testPartExecutor
    yield
  File "/usr/lib/python3.8/unittest/case.py", line 676, in run
    self._callTestMethod(testMethod)
  File "/usr/lib/python3.8/unittest/case.py", line 633, in _callTestMethod
    method()
  File "/opt/ros/noetic/lib/python3/dist-packages/rostest/runner.py", line 93, in fn
    self.fail(message)
  File "/usr/lib/python3.8/unittest/case.py", line 753, in fail
    raise self.failureException(msg)
--------------------------------------------------------------------------------
[Testcase: testt3325] ... FAILURE!
FAILURE: Package [fcsmap_fcs_suite_t3325] for test node [fcsmap_fcs_suite_t3325/node] does not exist
  File "/usr/lib/python3.8/unittest/case.py", line 60, in testPartExecutor
    yield
  File "/usr/lib/python3.8/unittest/case.py", line 676, in run
    self._callTestMethod(testMethod)
  File "/usr/lib/python3.8/unittest/case.py", line 633, in _callTestMethod
    method()
  File "/opt/ros/noetic/lib/python3/dist-packages/rostest/runner.py", line 93, in fn
    self.fail(message)
  File "/usr/lib/python3.8/unittest/case.py", line 753, in fail
    raise self.failureException(msg)
--------------------------------------------------------------------------------
[Testcase: testt3326] ... FAILURE!
FAILURE: Package [fcsmap_fcs_suite_t3326] for test node [fcsmap_fcs_suite_t3326/node] does not exist
  File "/usr/lib/python3.8/unittest/case.py", line 60, in testPartExecutor
    yield
  File "/usr/lib/python3.8/unittest/case.py", line 676, in run
    self._callTestMethod(testMethod)
  File "/usr/lib/python3.8/unittest/case.py", line 633, in _callTestMethod
    method()
  File "/opt/ros/noetic/lib/python3/dist-packages/rostest/runner.py", line 93, in fn
    self.fail(message)
  File "/usr/lib/python3.8/unittest/case.py", line 753, in fail
    raise self.failureException(msg)
--------------------------------------------------------------------------------
[Testcase: testt3327] ... FAILURE!
FAILURE: Package [fcsmap_fcs_suite_t3327] for test node [fcsmap_fcs_suite_t3327/node] does not exist
  File "/usr/lib/python3.8/unittest/case.py", line 60, in testPartExecutor
    yield
  File "/usr/lib/python3.8/unittest/case.py", line 676, in run
    self._callTestMethod(testMethod)
  File "/usr/lib/python3.8/unittest/case.py", line 633, in _callTestMethod
    method()
  File "/opt/ros/noetic/lib/python3/dist-packages/rostest/runner.py", line 93, in fn
    self.fail(message)
  File "/usr/lib/python3.8/unittest/case.py", line 753, in fail
    raise self.failureException(msg)
--------------------------------------------------------------------------------
[Testcase: testt3328] ... FAILURE!
FAILURE: Package [fcsmap_fcs_suite_t3328] for test node [fcsmap_fcs_suite_t3328/node] does not exist
  File "/usr/lib/python3.8/unittest/case.py", line 60, in testPartExecutor
    yield
  File "/usr/lib/python3.8/unittest/case.py", line 676, in run
    self._callTestMethod(testMethod)
  File "/usr/lib/python3.8/unittest/case.py", line 633, in _callTestMethod
    method()
  File "/opt/ros/noetic/lib/python3/dist-packages/rostest/runner.py", line 93, in fn
    self.fail(message)
  File "/usr/lib/python3.8/unittest/case.py", line 753, in fail
    raise self.failureException(msg)
--------------------------------------------------------------------------------
[Testcase: testt3329] ... FAILURE!
FAILURE: Package [fcsmap_fcs_suite_t3329] for test node [fcsmap_fcs_suite_t3329/node] does not exist
  File "/usr/lib/python3.8/unittest/case.py", line 60, in testPartExecutor
    yield
  File "/usr/lib/python3.8/unittest/case.py", line 676, in run
    self._callTestMethod(testMethod)
  File "/usr/lib/python3.8/unittest/case.py", line 633, in _callTestMethod
    method()
  File "/opt/ros/noetic/lib/python3/dist-packages/rostest/runner.py", line 93, in fn
    self.fail(message)
  File "/usr/lib/python3.8/unittest/case.py", line 753, in fail
    raise self.failureException(msg)
--------------------------------------------------------------------------------
[Testcase: testt3330] ... FAILURE!
FAILURE: Package [fcsmap_fcs_suite_t3330] for test node [fcsmap_fcs_suite_t3330/node] does not exist
  File "/usr/lib/python3.8/unittest/case.py", line 60, in testPartExecutor
    yield
  File "/usr/lib/python3.8/unittest/case.py", line 676, in run
    self._callTestMethod(testMethod)
  File "/usr/lib/python3.8/unittest/case.py", line 633, in _callTestMethod
    method()
  File "/opt/ros/noetic/lib/python3/dist-packages/rostest/runner.py", line 93, in fn
    self.fail(message)
  File "/usr/lib/python3.8/unittest/case.py", line 753, in fail
    raise self.failureException(msg)
--------------------------------------------------------------------------------
[Testcase: testt3331] ... FAILURE!
FAILURE: Package [fcsmap_fcs_suite_t3331] for test node [fcsmap_fcs_suite_t3331/node] does not exist
  File "/usr/lib/python3.8/unittest/case.py", line 60, in testPartExecutor
    yield
  File "/usr/lib/python3.8/unittest/case.py", line 676, in run
    self._callTestMethod(testMethod)
  File "/usr/lib/python3.8/unittest/case.py", line 633, in _callTestMethod
    method()
  File "/opt/ros/noetic/lib/python3/dist-packages/rostest/runner.py", line 93, in fn
    self.fail(message)
  File "/usr/lib/python3.8/unittest/case.py", line 753, in fail
    raise self.failureException(msg)
--------------------------------------------------------------------------------
[Testcase: testt3332] ... FAILURE!
FAILURE: Package [fcsmap_fcs_suite_t3332] for test node [fcsmap_fcs_suite_t3332/node] does not exist
  File "/usr/lib/python3.8/unittest/case.py", line 60, in testPartExecutor
    yield
  File "/usr/lib/python3.8/unittest/case.py", line 676, in run
    self._callTestMethod(testMethod)
  File "/usr/lib/python3.8/unittest/case.py", line 633, in _callTestMethod
    method()
  File "/opt/ros/noetic/lib/python3/dist-packages/rostest/runner.py", line 93, in fn
    self.fail(message)
  File "/usr/lib/python3.8/unittest/case.py", line 753, in fail
    raise self.failureException(msg)
--------------------------------------------------------------------------------
[Testcase: testt3333] ... FAILURE!
FAILURE: Package [fcsmap_fcs_suite_t3333] for test node [fcsmap_fcs_suite_t3333/node] does not exist
  File "/usr/lib/python3.8/unittest/case.py", line 60, in testPartExecutor
    yield
  File "/usr/lib/python3.8/unittest/case.py", line 676, in run
    self._callTestMethod(testMethod)
  File "/usr/lib/python3.8/unittest/case.py", line 633, in _callTestMethod
    method()
  File "/opt/ros/noetic/lib/python3/dist-packages/rostest/runner.py", line 93, in fn
    self.fail(message)
  File "/usr/lib/python3.8/unittest/case.py", line 753, in fail
    raise self.failureException(msg)
--------------------------------------------------------------------------------
[Testcase: testt3334] ... FAILURE!
FAILURE: Package [fcsmap_fcs_suite_t3334] for test node [fcsmap_fcs_suite_t3334/node] does not exist
  File "/usr/lib/python3.8/unittest/case.py", line 60, in testPartExecutor
    yield
  File "/usr/lib/python3.8/unittest/case.py", line 676, in run
    self._callTestMethod(testMethod)
  File "/usr/lib/python3.8/unittest/case.py", line 633, in _callTestMethod
    method()
  File "/opt/ros/noetic/lib/python3/dist-packages/rostest/runner.py", line 93, in fn
    self.fail(message)
  File "/usr/lib/python3.8/unittest/case.py", line 753, in fail
    raise self.failureException(msg)
--------------------------------------------------------------------------------
[Testcase: testt3335] ... FAILURE!
FAILURE: Package [fcsmap_fcs_suite_t3335] for test node [fcsmap_fcs_suite_t3335/node] does not exist
  File "/usr/lib/python3.8/unittest/case.py", line 60, in testPartExecutor
    yield
  File "/usr/lib/python3.8/unittest/case.py", line 676, in run
    self._callTestMethod(testMethod)
  File "/usr/lib/python3.8/unittest/case.py", line 633, in _callTestMethod
    method()
  File "/opt/ros/noetic/lib/python3/dist-packages/rostest/runner.py", line 93, in fn
    self.fail(message)
  File "/usr/lib/python3.8/unittest/case.py", line 753, in fail
    raise self.failureException(msg)
--------------------------------------------------------------------------------
[Testcase: testt3336] ... FAILURE!
FAILURE: Package [fcsmap_fcs_suite_t3336] for test node [fcsmap_fcs_suite_t3336/node] does not exist
  File "/usr/lib/python3.8/unittest/case.py", line 60, in testPartExecutor
    yield
  File "/usr/lib/python3.8/unittest/case.py", line 676, in run
    self._callTestMethod(testMethod)
  File "/usr/lib/python3.8/unittest/case.py", line 633, in _callTestMethod
    method()
  File "/opt/ros/noetic/lib/python3/dist-packages/rostest/runner.py", line 93, in fn
    self.fail(message)
  File "/usr/lib/python3.8/unittest/case.py", line 753, in fail
    raise self.failureException(msg)
--------------------------------------------------------------------------------
[Testcase: testt3337] ... FAILURE!
FAILURE: Package [fcsmap_fcs_suite_t3337] for test node [fcsmap_fcs_suite_t3337/node] does not exist
  File "/usr/lib/python3.8/unittest/case.py", line 60, in testPartExecutor
    yield
  File "/usr/lib/python3.8/unittest/case.py", line 676, in run
    self._callTestMethod(testMethod)
  File "/usr/lib/python3.8/unittest/case.py", line 633, in _callTestMethod
    method()
  File "/opt/ros/noetic/lib/python3/dist-packages/rostest/runner.py", line 93, in fn
    self.fail(message)
  File "/usr/lib/python3.8/unittest/case.py", line 753, in fail
    raise self.failureException(msg)
--------------------------------------------------------------------------------
[Testcase: testt3338] ... FAILURE!
FAILURE: Package [fcsmap_fcs_suite_t3338] for test node [fcsmap_fcs_suite_t3338/node] does not exist
  File "/usr/lib/python3.8/unittest/case.py", line 60, in testPartExecutor
    yield
  File "/usr/lib/python3.8/unittest/case.py", line 676, in run
    self._callTestMethod(testMethod)
  File "/usr/lib/python3.8/unittest/case.py", line 633, in _callTestMethod
    method()
  File "/opt/ros/noetic/lib/python3/dist-packages/rostest/runner.py", line 93, in fn
    self.fail(message)
  File "/usr/lib/python3.8/unittest/case.py", line 753, in fail
    raise self.failureException(msg)
--------------------------------------------------------------------------------
[Testcase: testt3341] ... FAILURE!
FAILURE: Package [fcsmap_fcs_suite_t3341] for test node [fcsmap_fcs_suite_t3341/node] does not exist
  File "/usr/lib/python3.8/unittest/case.py", line 60, in testPartExecutor
    yield
  File "/usr/lib/python3.8/unittest/case.py", line 676, in run
    self._callTestMethod(testMethod)
  File "/usr/lib/python3.8/unittest/case.py", line 633, in _callTestMethod
    method()
  File "/opt/ros/noetic/lib/python3/dist-packages/rostest/runner.py", line 93, in fn
    self.fail(message)
  File "/usr/lib/python3.8/unittest/case.py", line 753, in fail
    raise self.failureException(msg)
--------------------------------------------------------------------------------
[Testcase: testt3342] ... FAILURE!
FAILURE: Package [fcsmap_fcs_suite_t3342] for test node [fcsmap_fcs_suite_t3342/node] does not exist
  File "/usr/lib/python3.8/unittest/case.py", line 60, in testPartExecutor
    yield
  File "/usr/lib/python3.8/unittest/case.py", line 676, in run
    self._callTestMethod(testMethod)
  File "/usr/lib/python3.8/unittest/case.py", line 633, in _callTestMethod
    method()
  File "/opt/ros/noetic/lib/python3/dist-packages/rostest/runner.py", line 93, in fn
    self.fail(message)
  File "/usr/lib/python3.8/unittest/case.py", line 753, in fail
    raise self.failureException(msg)
--------------------------------------------------------------------------------
[Testcase: testt3343] ... FAILURE!
FAILURE: Package [fcsmap_fcs_suite_t3343] for test node [fcsmap_fcs_suite_t3343/node] does not exist
  File "/usr/lib/python3.8/unittest/case.py", line 60, in testPartExecutor
    yield
  File "/usr/lib/python3.8/unittest/case.py", line 676, in run
    self._callTestMethod(testMethod)
  File "/usr/lib/python3.8/unittest/case.py", line 633, in _callTestMethod
    method()
  File "/opt/ros/noetic/lib/python3/dist-packages/rostest/runner.py", line 93, in fn
    self.fail(message)
  File "/usr/lib/python3.8/unittest/case.py", line 753, in fail
    raise self.failureException(msg)
--------------------------------------------------------------------------------
[Testcase: testt3344] ... FAILURE!
FAILURE: Package [fcsmap_fcs_suite_t3344] for test node [fcsmap_fcs_suite_t3344/node] does not exist
  File "/usr/lib/python3.8/unittest/case.py", line 60, in testPartExecutor
    yield
  File "/usr/lib/python3.8/unittest/case.py", line 676, in run
    self._callTestMethod(testMethod)
  File "/usr/lib/python3.8/unittest/case.py", line 633, in _callTestMethod
    method()
  File "/opt/ros/noetic/lib/python3/dist-packages/rostest/runner.py", line 93, in fn
    self.fail(message)
  File "/usr/lib/python3.8/unittest/case.py", line 753, in fail
    raise self.failureException(msg)
--------------------------------------------------------------------------------
[Testcase: testt3345] ... FAILURE!
FAILURE: Package [fcsmap_fcs_suite_t3345] for test node [fcsmap_fcs_suite_t3345/node] does not exist
  File "/usr/lib/python3.8/unittest/case.py", line 60, in testPartExecutor
    yield
  File "/usr/lib/python3.8/unittest/case.py", line 676, in run
    self._callTestMethod(testMethod)
  File "/usr/lib/python3.8/unittest/case.py", line 633, in _callTestMethod
    method()
  File "/opt/ros/noetic/lib/python3/dist-packages/rostest/runner.py", line 93, in fn
    self.fail(message)
  File "/usr/lib/python3.8/unittest/case.py", line 753, in fail
    raise self.failureException(msg)
--------------------------------------------------------------------------------
[Testcase: testt3346] ... FAILURE!
FAILURE: Package [fcsmap_fcs_suite_t3346] for test node [fcsmap_fcs_suite_t3346/node] does not exist
  File "/usr/lib/python3.8/unittest/case.py", line 60, in testPartExecutor
    yield
  File "/usr/lib/python3.8/unittest/case.py", line 676, in run
    self._callTestMethod(testMethod)
  File "/usr/lib/python3.8/unittest/case.py", line 633, in _callTestMethod
    method()
  File "/opt/ros/noetic/lib/python3/dist-packages/rostest/runner.py", line 93, in fn
    self.fail(message)
  File "/usr/lib/python3.8/unittest/case.py", line 753, in fail
    raise self.failureException(msg)
--------------------------------------------------------------------------------
[Testcase: testt3347] ... FAILURE!
FAILURE: Package [fcsmap_fcs_suite_t3347] for test node [fcsmap_fcs_suite_t3347/node] does not exist
  File "/usr/lib/python3.8/unittest/case.py", line 60, in testPartExecutor
    yield
  File "/usr/lib/python3.8/unittest/case.py", line 676, in run
    self._callTestMethod(testMethod)
  File "/usr/lib/python3.8/unittest/case.py", line 633, in _callTestMethod
    method()
  File "/opt/ros/noetic/lib/python3/dist-packages/rostest/runner.py", line 93, in fn
    self.fail(message)
  File "/usr/lib/python3.8/unittest/case.py", line 753, in fail
    raise self.failureException(msg)
--------------------------------------------------------------------------------
[Testcase: testt3348] ... FAILURE!
FAILURE: Package [fcsmap_fcs_suite_t3348] for test node [fcsmap_fcs_suite_t3348/node] does not exist
  File "/usr/lib/python3.8/unittest/case.py", line 60, in testPartExecutor
    yield
  File "/usr/lib/python3.8/unittest/case.py", line 676, in run
    self._callTestMethod(testMethod)
  File "/usr/lib/python3.8/unittest/case.py", line 633, in _callTestMethod
    method()
  File "/opt/ros/noetic/lib/python3/dist-packages/rostest/runner.py", line 93, in fn
    self.fail(message)
  File "/usr/lib/python3.8/unittest/case.py", line 753, in fail
    raise self.failureException(msg)
--------------------------------------------------------------------------------
[Testcase: testt3349] ... FAILURE!
FAILURE: Package [fcsmap_fcs_suite_t3349] for test node [fcsmap_fcs_suite_t3349/node] does not exist
  File "/usr/lib/python3.8/unittest/case.py", line 60, in testPartExecutor
    yield
  File "/usr/lib/python3.8/unittest/case.py", line 676, in run
    self._callTestMethod(testMethod)
  File "/usr/lib/python3.8/unittest/case.py", line 633, in _callTestMethod
    method()
  File "/opt/ros/noetic/lib/python3/dist-packages/rostest/runner.py", line 93, in fn
    self.fail(message)
  File "/usr/lib/python3.8/unittest/case.py", line 753, in fail
    raise self.failureException(msg)
--------------------------------------------------------------------------------
[Testcase: testt3350] ... FAILURE!
FAILURE: Package [fcsmap_fcs_suite_t3350] for test node [fcsmap_fcs_suite_t3350/node] does not exist
  File "/usr/lib/python3.8/unittest/case.py", line 60, in testPartExecutor
    yield
  File "/usr/lib/python3.8/unittest/case.py", line 676, in run
    self._callTestMethod(testMethod)
  File "/usr/lib/python3.8/unittest/case.py", line 633, in _callTestMethod
    method()
  File "/opt/ros/noetic/lib/python3/dist-packages/rostest/runner.py", line 93, in fn
    self.fail(message)
  File "/usr/lib/python3.8/unittest/case.py", line 753, in fail
    raise self.failureException(msg)
--------------------------------------------------------------------------------
[Testcase: testt3351] ... FAILURE!
FAILURE: Package [fcsmap_fcs_suite_t3351] for test node [fcsmap_fcs_suite_t3351/node] does not exist
  File "/usr/lib/python3.8/unittest/case.py", line 60, in testPartExecutor
    yield
  File "/usr/lib/python3.8/unittest/case.py", line 676, in run
    self._callTestMethod(testMethod)
  File "/usr/lib/python3.8/unittest/case.py", line 633, in _callTestMethod
    method()
  File "/opt/ros/noetic/lib/python3/dist-packages/rostest/runner.py", line 93, in fn
    self.fail(message)
  File "/usr/lib/python3.8/unittest/case.py", line 753, in fail
    raise self.failureException(msg)
--------------------------------------------------------------------------------
[Testcase: testt3352] ... FAILURE!
FAILURE: Package [fcsmap_fcs_suite_t3352] for test node [fcsmap_fcs_suite_t3352/node] does not exist
  File "/usr/lib/python3.8/unittest/case.py", line 60, in testPartExecutor
    yield
  File "/usr/lib/python3.8/unittest/case.py", line 676, in run
    self._callTestMethod(testMethod)
  File "/usr/lib/python3.8/unittest/case.py", line 633, in _callTestMethod
    method()
  File "/opt/ros/noetic/lib/python3/dist-packages/rostest/runner.py", line 93, in fn
    self.fail(message)
  File "/usr/lib/python3.8/unittest/case.py", line 753, in fail
    raise self.failureException(msg)
--------------------------------------------------------------------------------
[Testcase: testt3353] ... FAILURE!
FAILURE: Package [fcsmap_fcs_suite_t3353] for test node [fcsmap_fcs_suite_t3353/node] does not exist
  File "/usr/lib/python3.8/unittest/case.py", line 60, in testPartExecutor
    yield
  File "/usr/lib/python3.8/unittest/case.py", line 676, in run
    self._callTestMethod(testMethod)
  File "/usr/lib/python3.8/unittest/case.py", line 633, in _callTestMethod
    method()
  File "/opt/ros/noetic/lib/python3/dist-packages/rostest/runner.py", line 93, in fn
    self.fail(message)
  File "/usr/lib/python3.8/unittest/case.py", line 753, in fail
    raise self.failureException(msg)
--------------------------------------------------------------------------------
[Testcase: testt3354] ... FAILURE!
FAILURE: Package [fcsmap_fcs_suite_t3354] for test node [fcsmap_fcs_suite_t3354/node] does not exist
  File "/usr/lib/python3.8/unittest/case.py", line 60, in testPartExecutor
    yield
  File "/usr/lib/python3.8/unittest/case.py", line 676, in run
    self._callTestMethod(testMethod)
  File "/usr/lib/python3.8/unittest/case.py", line 633, in _callTestMethod
    method()
  File "/opt/ros/noetic/lib/python3/dist-packages/rostest/runner.py", line 93, in fn
    self.fail(message)
  File "/usr/lib/python3.8/unittest/case.py", line 753, in fail
    raise self.failureException(msg)
--------------------------------------------------------------------------------
[Testcase: testt3355] ... FAILURE!
FAILURE: Package [fcsmap_fcs_suite_t3355] for test node [fcsmap_fcs_suite_t3355/node] does not exist
  File "/usr/lib/python3.8/unittest/case.py", line 60, in testPartExecutor
    yield
  File "/usr/lib/python3.8/unittest/case.py", line 676, in run
    self._callTestMethod(testMethod)
  File "/usr/lib/python3.8/unittest/case.py", line 633, in _callTestMethod
    method()
  File "/opt/ros/noetic/lib/python3/dist-packages/rostest/runner.py", line 93, in fn
    self.fail(message)
  File "/usr/lib/python3.8/unittest/case.py", line 753, in fail
    raise self.failureException(msg)
--------------------------------------------------------------------------------
[Testcase: testt3356] ... FAILURE!
FAILURE: Package [fcsmap_fcs_suite_t3356] for test node [fcsmap_fcs_suite_t3356/node] does not exist
  File "/usr/lib/python3.8/unittest/case.py", line 60, in testPartExecutor
    yield
  File "/usr/lib/python3.8/unittest/case.py", line 676, in run
    self._callTestMethod(testMethod)
  File "/usr/lib/python3.8/unittest/case.py", line 633, in _callTestMethod
    method()
  File "/opt/ros/noetic/lib/python3/dist-packages/rostest/runner.py", line 93, in fn
    self.fail(message)
  File "/usr/lib/python3.8/unittest/case.py", line 753, in fail
    raise self.failureException(msg)
--------------------------------------------------------------------------------
[Testcase: testt3357] ... FAILURE!
FAILURE: Package [fcsmap_fcs_suite_t3357] for test node [fcsmap_fcs_suite_t3357/node] does not exist
  File "/usr/lib/python3.8/unittest/case.py", line 60, in testPartExecutor
    yield
  File "/usr/lib/python3.8/unittest/case.py", line 676, in run
    self._callTestMethod(testMethod)
  File "/usr/lib/python3.8/unittest/case.py", line 633, in _callTestMethod
    method()
  File "/opt/ros/noetic/lib/python3/dist-packages/rostest/runner.py", line 93, in fn
    self.fail(message)
  File "/usr/lib/python3.8/unittest/case.py", line 753, in fail
    raise self.failureException(msg)
--------------------------------------------------------------------------------
[Testcase: testt3358] ... FAILURE!
FAILURE: Package [fcsmap_fcs_suite_t3358] for test node [fcsmap_fcs_suite_t3358/node] does not exist
  File "/usr/lib/python3.8/unittest/case.py", line 60, in testPartExecutor
    yield
  File "/usr/lib/python3.8/unittest/case.py", line 676, in run
    self._callTestMethod(testMethod)
  File "/usr/lib/python3.8/unittest/case.py", line 633, in _callTestMethod
    method()
  File "/opt/ros/noetic/lib/python3/dist-packages/rostest/runner.py", line 93, in fn
    self.fail(message)
  File "/usr/lib/python3.8/unittest/case.py", line 753, in fail
    raise self.failureException(msg)
--------------------------------------------------------------------------------
[Testcase: testt3359] ... FAILURE!
FAILURE: Package [fcsmap_fcs_suite_t3359] for test node [fcsmap_fcs_suite_t3359/node] does not exist
  File "/usr/lib/python3.8/unittest/case.py", line 60, in testPartExecutor
    yield
  File "/usr/lib/python3.8/unittest/case.py", line 676, in run
    self._callTestMethod(testMethod)
  File "/usr/lib/python3.8/unittest/case.py", line 633, in _callTestMethod
    method()
  File "/opt/ros/noetic/lib/python3/dist-packages/rostest/runner.py", line 93, in fn
    self.fail(message)
  File "/usr/lib/python3.8/unittest/case.py", line 753, in fail
    raise self.failureException(msg)
--------------------------------------------------------------------------------
[Testcase: testt3360] ... FAILURE!
FAILURE: Package [fcsmap_fcs_suite_t3360] for test node [fcsmap_fcs_suite_t3360/node] does not exist
  File "/usr/lib/python3.8/unittest/case.py", line 60, in testPartExecutor
    yield
  File "/usr/lib/python3.8/unittest/case.py", line 676, in run
    self._callTestMethod(testMethod)
  File "/usr/lib/python3.8/unittest/case.py", line 633, in _callTestMethod
    method()
  File "/opt/ros/noetic/lib/python3/dist-packages/rostest/runner.py", line 93, in fn
    self.fail(message)
  File "/usr/lib/python3.8/unittest/case.py", line 753, in fail
    raise self.failureException(msg)
--------------------------------------------------------------------------------
[Testcase: testt3361] ... FAILURE!
FAILURE: Package [fcsmap_fcs_suite_t3361] for test node [fcsmap_fcs_suite_t3361/node] does not exist
  File "/usr/lib/python3.8/unittest/case.py", line 60, in testPartExecutor
    yield
  File "/usr/lib/python3.8/unittest/case.py", line 676, in run
    self._callTestMethod(testMethod)
  File "/usr/lib/python3.8/unittest/case.py", line 633, in _callTestMethod
    method()
  File "/opt/ros/noetic/lib/python3/dist-packages/rostest/runner.py", line 93, in fn
    self.fail(message)
  File "/usr/lib/python3.8/unittest/case.py", line 753, in fail
    raise self.failureException(msg)
--------------------------------------------------------------------------------
[Testcase: testt3362] ... FAILURE!
FAILURE: Package [fcsmap_fcs_suite_t3362] for test node [fcsmap_fcs_suite_t3362/node] does not exist
  File "/usr/lib/python3.8/unittest/case.py", line 60, in testPartExecutor
    yield
  File "/usr/lib/python3.8/unittest/case.py", line 676, in run
    self._callTestMethod(testMethod)
  File "/usr/lib/python3.8/unittest/case.py", line 633, in _callTestMethod
    method()
  File "/opt/ros/noetic/lib/python3/dist-packages/rostest/runner.py", line 93, in fn
    self.fail(message)
  File "/usr/lib/python3.8/unittest/case.py", line 753, in fail
    raise self.failureException(msg)
--------------------------------------------------------------------------------
[Testcase: testt3363] ... FAILURE!
FAILURE: Package [fcsmap_fcs_suite_t3363] for test node [fcsmap_fcs_suite_t3363/node] does not exist
  File "/usr/lib/python3.8/unittest/case.py", line 60, in testPartExecutor
    yield
  File "/usr/lib/python3.8/unittest/case.py", line 676, in run
    self._callTestMethod(testMethod)
  File "/usr/lib/python3.8/unittest/case.py", line 633, in _callTestMethod
    method()
  File "/opt/ros/noetic/lib/python3/dist-packages/rostest/runner.py", line 93, in fn
    self.fail(message)
  File "/usr/lib/python3.8/unittest/case.py", line 753, in fail
    raise self.failureException(msg)
--------------------------------------------------------------------------------
[Testcase: testt3364] ... FAILURE!
FAILURE: Package [fcsmap_fcs_suite_t3364] for test node [fcsmap_fcs_suite_t3364/node] does not exist
  File "/usr/lib/python3.8/unittest/case.py", line 60, in testPartExecutor
    yield
  File "/usr/lib/python3.8/unittest/case.py", line 676, in run
    self._callTestMethod(testMethod)
  File "/usr/lib/python3.8/unittest/case.py", line 633, in _callTestMethod
    method()
  File "/opt/ros/noetic/lib/python3/dist-packages/rostest/runner.py", line 93, in fn
    self.fail(message)
  File "/usr/lib/python3.8/unittest/case.py", line 753, in fail
    raise self.failureException(msg)
--------------------------------------------------------------------------------
[Testcase: testt3365] ... FAILURE!
FAILURE: Package [fcsmap_fcs_suite_t3365] for test node [fcsmap_fcs_suite_t3365/node] does not exist
  File "/usr/lib/python3.8/unittest/case.py", line 60, in testPartExecutor
    yield
  File "/usr/lib/python3.8/unittest/case.py", line 676, in run
    self._callTestMethod(testMethod)
  File "/usr/lib/python3.8/unittest/case.py", line 633, in _callTestMethod
    method()
  File "/opt/ros/noetic/lib/python3/dist-packages/rostest/runner.py", line 93, in fn
    self.fail(message)
  File "/usr/lib/python3.8/unittest/case.py", line 753, in fail
    raise self.failureException(msg)
--------------------------------------------------------------------------------
[Testcase: testt3366] ... FAILURE!
FAILURE: Package [fcsmap_fcs_suite_t3366] for test node [fcsmap_fcs_suite_t3366/node] does not exist
  File "/usr/lib/python3.8/unittest/case.py", line 60, in testPartExecutor
    yield
  File "/usr/lib/python3.8/unittest/case.py", line 676, in run
    self._callTestMethod(testMethod)
  File "/usr/lib/python3.8/unittest/case.py", line 633, in _callTestMethod
    method()
  File "/opt/ros/noetic/lib/python3/dist-packages/rostest/runner.py", line 93, in fn
    self.fail(message)
  File "/usr/lib/python3.8/unittest/case.py", line 753, in fail
    raise self.failureException(msg)
--------------------------------------------------------------------------------
[Testcase: testt3367] ... FAILURE!
FAILURE: Package [fcsmap_fcs_suite_t3367] for test node [fcsmap_fcs_suite_t3367/node] does not exist
  File "/usr/lib/python3.8/unittest/case.py", line 60, in testPartExecutor
    yield
  File "/usr/lib/python3.8/unittest/case.py", line 676, in run
    self._callTestMethod(testMethod)
  File "/usr/lib/python3.8/unittest/case.py", line 633, in _callTestMethod
    method()
  File "/opt/ros/noetic/lib/python3/dist-packages/rostest/runner.py", line 93, in fn
    self.fail(message)
  File "/usr/lib/python3.8/unittest/case.py", line 753, in fail
    raise self.failureException(msg)
--------------------------------------------------------------------------------
[Testcase: testt3368] ... FAILURE!
FAILURE: Package [fcsmap_fcs_suite_t3368] for test node [fcsmap_fcs_suite_t3368/node] does not exist
  File "/usr/lib/python3.8/unittest/case.py", line 60, in testPartExecutor
    yield
  File "/usr/lib/python3.8/unittest/case.py", line 676, in run
    self._callTestMethod(testMethod)
  File "/usr/lib/python3.8/unittest/case.py", line 633, in _callTestMethod
    method()
  File "/opt/ros/noetic/lib/python3/dist-packages/rostest/runner.py", line 93, in fn
    self.fail(message)
  File "/usr/lib/python3.8/unittest/case.py", line 753, in fail
    raise self.failureException(msg)
--------------------------------------------------------------------------------
[Testcase: testt3369] ... FAILURE!
FAILURE: Package [fcsmap_fcs_suite_t3369] for test node [fcsmap_fcs_suite_t3369/node] does not exist
  File "/usr/lib/python3.8/unittest/case.py", line 60, in testPartExecutor
    yield
  File "/usr/lib/python3.8/unittest/case.py", line 676, in run
    self._callTestMethod(testMethod)
  File "/usr/lib/python3.8/unittest/case.py", line 633, in _callTestMethod
    method()
  File "/opt/ros/noetic/lib/python3/dist-packages/rostest/runner.py", line 93, in fn
    self.fail(message)
  File "/usr/lib/python3.8/unittest/case.py", line 753, in fail
    raise self.failureException(msg)
--------------------------------------------------------------------------------
[Testcase: testt3370] ... FAILURE!
FAILURE: Package [fcsmap_fcs_suite_t3370] for test node [fcsmap_fcs_suite_t3370/node] does not exist
  File "/usr/lib/python3.8/unittest/case.py", line 60, in testPartExecutor
    yield
  File "/usr/lib/python3.8/unittest/case.py", line 676, in run
    self._callTestMethod(testMethod)
  File "/usr/lib/python3.8/unittest/case.py", line 633, in _callTestMethod
    method()
  File "/opt/ros/noetic/lib/python3/dist-packages/rostest/runner.py", line 93, in fn
    self.fail(message)
  File "/usr/lib/python3.8/unittest/case.py", line 753, in fail
    raise self.failureException(msg)
--------------------------------------------------------------------------------
[Testcase: testt3371] ... FAILURE!
FAILURE: Package [fcsmap_fcs_suite_t3371] for test node [fcsmap_fcs_suite_t3371/node] does not exist
  File "/usr/lib/python3.8/unittest/case.py", line 60, in testPartExecutor
    yield
  File "/usr/lib/python3.8/unittest/case.py", line 676, in run
    self._callTestMethod(testMethod)
  File "/usr/lib/python3.8/unittest/case.py", line 633, in _callTestMethod
    method()
  File "/opt/ros/noetic/lib/python3/dist-packages/rostest/runner.py", line 93, in fn
    self.fail(message)
  File "/usr/lib/python3.8/unittest/case.py", line 753, in fail
    raise self.failureException(msg)
--------------------------------------------------------------------------------
[Testcase: testt3372] ... FAILURE!
FAILURE: Package [fcsmap_fcs_suite_t3372] for test node [fcsmap_fcs_suite_t3372/node] does not exist
  File "/usr/lib/python3.8/unittest/case.py", line 60, in testPartExecutor
    yield
  File "/usr/lib/python3.8/unittest/case.py", line 676, in run
    self._callTestMethod(testMethod)
  File "/usr/lib/python3.8/unittest/case.py", line 633, in _callTestMethod
    method()
  File "/opt/ros/noetic/lib/python3/dist-packages/rostest/runner.py", line 93, in fn
    self.fail(message)
  File "/usr/lib/python3.8/unittest/case.py", line 753, in fail
    raise self.failureException(msg)
--------------------------------------------------------------------------------
[Testcase: testt3373] ... FAILURE!
FAILURE: Package [fcsmap_fcs_suite_t3373] for test node [fcsmap_fcs_suite_t3373/node] does not exist
  File "/usr/lib/python3.8/unittest/case.py", line 60, in testPartExecutor
    yield
  File "/usr/lib/python3.8/unittest/case.py", line 676, in run
    self._callTestMethod(testMethod)
  File "/usr/lib/python3.8/unittest/case.py", line 633, in _callTestMethod
    method()
  File "/opt/ros/noetic/lib/python3/dist-packages/rostest/runner.py", line 93, in fn
    self.fail(message)
  File "/usr/lib/python3.8/unittest/case.py", line 753, in fail
    raise self.failureException(msg)
--------------------------------------------------------------------------------
[Testcase: testt3374] ... FAILURE!
FAILURE: Package [fcsmap_fcs_suite_t3374] for test node [fcsmap_fcs_suite_t3374/node] does not exist
  File "/usr/lib/python3.8/unittest/case.py", line 60, in testPartExecutor
    yield
  File "/usr/lib/python3.8/unittest/case.py", line 676, in run
    self._callTestMethod(testMethod)
  File "/usr/lib/python3.8/unittest/case.py", line 633, in _callTestMethod
    method()
  File "/opt/ros/noetic/lib/python3/dist-packages/rostest/runner.py", line 93, in fn
    self.fail(message)
  File "/usr/lib/python3.8/unittest/case.py", line 753, in fail
    raise self.failureException(msg)
--------------------------------------------------------------------------------
[Testcase: testt3375] ... FAILURE!
FAILURE: Package [fcsmap_fcs_suite_t3375] for test node [fcsmap_fcs_suite_t3375/node] does not exist
  File "/usr/lib/python3.8/unittest/case.py", line 60, in testPartExecutor
    yield
  File "/usr/lib/python3.8/unittest/case.py", line 676, in run
    self._callTestMethod(testMethod)
  File "/usr/lib/python3.8/unittest/case.py", line 633, in _callTestMethod
    method()
  File "/opt/ros/noetic/lib/python3/dist-packages/rostest/runner.py", line 93, in fn
    self.fail(message)
  File "/usr/lib/python3.8/unittest/case.py", line 753, in fail
    raise self.failureException(msg)
--------------------------------------------------------------------------------
[Testcase: testt3376] ... FAILURE!
FAILURE: Package [fcsmap_fcs_suite_t3376] for test node [fcsmap_fcs_suite_t3376/node] does not exist
  File "/usr/lib/python3.8/unittest/case.py", line 60, in testPartExecutor
    yield
  File "/usr/lib/python3.8/unittest/case.py", line 676, in run
    self._callTestMethod(testMethod)
  File "/usr/lib/python3.8/unittest/case.py", line 633, in _callTestMethod
    method()
  File "/opt/ros/noetic/lib/python3/dist-packages/rostest/runner.py", line 93, in fn
    self.fail(message)
  File "/usr/lib/python3.8/unittest/case.py", line 753, in fail
    raise self.failureException(msg)
--------------------------------------------------------------------------------
[Testcase: testt3377] ... FAILURE!
FAILURE: Package [fcsmap_fcs_suite_t3377] for test node [fcsmap_fcs_suite_t3377/node] does not exist
  File "/usr/lib/python3.8/unittest/case.py", line 60, in testPartExecutor
    yield
  File "/usr/lib/python3.8/unittest/case.py", line 676, in run
    self._callTestMethod(testMethod)
  File "/usr/lib/python3.8/unittest/case.py", line 633, in _callTestMethod
    method()
  File "/opt/ros/noetic/lib/python3/dist-packages/rostest/runner.py", line 93, in fn
    self.fail(message)
  File "/usr/lib/python3.8/unittest/case.py", line 753, in fail
    raise self.failureException(msg)
--------------------------------------------------------------------------------
[Testcase: testt3378] ... FAILURE!
FAILURE: Package [fcsmap_fcs_suite_t3378] for test node [fcsmap_fcs_suite_t3378/node] does not exist
  File "/usr/lib/python3.8/unittest/case.py", line 60, in testPartExecutor
    yield
  File "/usr/lib/python3.8/unittest/case.py", line 676, in run
    self._callTestMethod(testMethod)
  File "/usr/lib/python3.8/unittest/case.py", line 633, in _callTestMethod
    method()
  File "/opt/ros/noetic/lib/python3/dist-packages/rostest/runner.py", line 93, in fn
    self.fail(message)
  File "/usr/lib/python3.8/unittest/case.py", line 753, in fail
    raise self.failureException(msg)
--------------------------------------------------------------------------------
[Testcase: testt3379] ... FAILURE!
FAILURE: Package [fcsmap_fcs_suite_t3379] for test node [fcsmap_fcs_suite_t3379/node] does not exist
  File "/usr/lib/python3.8/unittest/case.py", line 60, in testPartExecutor
    yield
  File "/usr/lib/python3.8/unittest/case.py", line 676, in run
    self._callTestMethod(testMethod)
  File "/usr/lib/python3.8/unittest/case.py", line 633, in _callTestMethod
    method()
  File "/opt/ros/noetic/lib/python3/dist-packages/rostest/runner.py", line 93, in fn
    self.fail(message)
  File "/usr/lib/python3.8/unittest/case.py", line 753, in fail
    raise self.failureException(msg)
--------------------------------------------------------------------------------
[Testcase: testt3380] ... FAILURE!
FAILURE: Package [fcsmap_fcs_suite_t3380] for test node [fcsmap_fcs_suite_t3380/node] does not exist
  File "/usr/lib/python3.8/unittest/case.py", line 60, in testPartExecutor
    yield
  File "/usr/lib/python3.8/unittest/case.py", line 676, in run
    self._callTestMethod(testMethod)
  File "/usr/lib/python3.8/unittest/case.py", line 633, in _callTestMethod
    method()
  File "/opt/ros/noetic/lib/python3/dist-packages/rostest/runner.py", line 93, in fn
    self.fail(message)
  File "/usr/lib/python3.8/unittest/case.py", line 753, in fail
    raise self.failureException(msg)
--------------------------------------------------------------------------------
[Testcase: testt3381] ... FAILURE!
FAILURE: Package [fcsmap_fcs_suite_t3381] for test node [fcsmap_fcs_suite_t3381/node] does not exist
  File "/usr/lib/python3.8/unittest/case.py", line 60, in testPartExecutor
    yield
  File "/usr/lib/python3.8/unittest/case.py", line 676, in run
    self._callTestMethod(testMethod)
  File "/usr/lib/python3.8/unittest/case.py", line 633, in _callTestMethod
    method()
  File "/opt/ros/noetic/lib/python3/dist-packages/rostest/runner.py", line 93, in fn
    self.fail(message)
  File "/usr/lib/python3.8/unittest/case.py", line 753, in fail
    raise self.failureException(msg)
--------------------------------------------------------------------------------
[Testcase: testt3382] ... FAILURE!
FAILURE: Package [fcsmap_fcs_suite_t3382] for test node [fcsmap_fcs_suite_t3382/node] does not exist
  File "/usr/lib/python3.8/unittest/case.py", line 60, in testPartExecutor
    yield
  File "/usr/lib/python3.8/unittest/case.py", line 676, in run
    self._callTestMethod(testMethod)
  File "/usr/lib/python3.8/unittest/case.py", line 633, in _callTestMethod
    method()
  File "/opt/ros/noetic/lib/python3/dist-packages/rostest/runner.py", line 93, in fn
    self.fail(message)
  File "/usr/lib/python3.8/unittest/case.py", line 753, in fail
    raise self.failureException(msg)
--------------------------------------------------------------------------------
[Testcase: testt3383] ... FAILURE!
FAILURE: Package [fcsmap_fcs_suite_t3383] for test node [fcsmap_fcs_suite_t3383/node] does not exist
  File "/usr/lib/python3.8/unittest/case.py", line 60, in testPartExecutor
    yield
  File "/usr/lib/python3.8/unittest/case.py", line 676, in run
    self._callTestMethod(testMethod)
  File "/usr/lib/python3.8/unittest/case.py", line 633, in _callTestMethod
    method()
  File "/opt/ros/noetic/lib/python3/dist-packages/rostest/runner.py", line 93, in fn
    self.fail(message)
  File "/usr/lib/python3.8/unittest/case.py", line 753, in fail
    raise self.failureException(msg)
--------------------------------------------------------------------------------
[Testcase: testt3384] ... FAILURE!
FAILURE: Package [fcsmap_fcs_suite_t3384] for test node [fcsmap_fcs_suite_t3384/node] does not exist
  File "/usr/lib/python3.8/unittest/case.py", line 60, in testPartExecutor
    yield
  File "/usr/lib/python3.8/unittest/case.py", line 676, in run
    self._callTestMethod(testMethod)
  File "/usr/lib/python3.8/unittest/case.py", line 633, in _callTestMethod
    method()
  File "/opt/ros/noetic/lib/python3/dist-packages/rostest/runner.py", line 93, in fn
    self.fail(message)
  File "/usr/lib/python3.8/unittest/case.py", line 753, in fail
    raise self.failureException(msg)
--------------------------------------------------------------------------------
[Testcase: testt3385] ... FAILURE!
FAILURE: Package [fcsmap_fcs_suite_t3385] for test node [fcsmap_fcs_suite_t3385/node] does not exist
  File "/usr/lib/python3.8/unittest/case.py", line 60, in testPartExecutor
    yield
  File "/usr/lib/python3.8/unittest/case.py", line 676, in run
    self._callTestMethod(testMethod)
  File "/usr/lib/python3.8/unittest/case.py", line 633, in _callTestMethod
    method()
  File "/opt/ros/noetic/lib/python3/dist-packages/rostest/runner.py", line 93, in fn
    self.fail(message)
  File "/usr/lib/python3.8/unittest/case.py", line 753, in fail
    raise self.failureException(msg)
--------------------------------------------------------------------------------
[Testcase: testt3386] ... FAILURE!
FAILURE: Package [fcsmap_fcs_suite_t3386] for test node [fcsmap_fcs_suite_t3386/node] does not exist
  File "/usr/lib/python3.8/unittest/case.py", line 60, in testPartExecutor
    yield
  File "/usr/lib/python3.8/unittest/case.py", line 676, in run
    self._callTestMethod(testMethod)
  File "/usr/lib/python3.8/unittest/case.py", line 633, in _callTestMethod
    method()
  File "/opt/ros/noetic/lib/python3/dist-packages/rostest/runner.py", line 93, in fn
    self.fail(message)
  File "/usr/lib/python3.8/unittest/case.py", line 753, in fail
    raise self.failureException(msg)
--------------------------------------------------------------------------------
[Testcase: testt3387] ... FAILURE!
FAILURE: Package [fcsmap_fcs_suite_t3387] for test node [fcsmap_fcs_suite_t3387/node] does not exist
  File "/usr/lib/python3.8/unittest/case.py", line 60, in testPartExecutor
    yield
  File "/usr/lib/python3.8/unittest/case.py", line 676, in run
    self._callTestMethod(testMethod)
  File "/usr/lib/python3.8/unittest/case.py", line 633, in _callTestMethod
    method()
  File "/opt/ros/noetic/lib/python3/dist-packages/rostest/runner.py", line 93, in fn
    self.fail(message)
  File "/usr/lib/python3.8/unittest/case.py", line 753, in fail
    raise self.failureException(msg)
--------------------------------------------------------------------------------
[Testcase: testt3388] ... FAILURE!
FAILURE: Package [fcsmap_fcs_suite_t3388] for test node [fcsmap_fcs_suite_t3388/node] does not exist
  File "/usr/lib/python3.8/unittest/case.py", line 60, in testPartExecutor
    yield
  File "/usr/lib/python3.8/unittest/case.py", line 676, in run
    self._callTestMethod(testMethod)
  File "/usr/lib/python3.8/unittest/case.py", line 633, in _callTestMethod
    method()
  File "/opt/ros/noetic/lib/python3/dist-packages/rostest/runner.py", line 93, in fn
    self.fail(message)
  File "/usr/lib/python3.8/unittest/case.py", line 753, in fail
    raise self.failureException(msg)
--------------------------------------------------------------------------------
[Testcase: testt3389] ... FAILURE!
FAILURE: Package [fcsmap_fcs_suite_t3389] for test node [fcsmap_fcs_suite_t3389/node] does not exist
  File "/usr/lib/python3.8/unittest/case.py", line 60, in testPartExecutor
    yield
  File "/usr/lib/python3.8/unittest/case.py", line 676, in run
    self._callTestMethod(testMethod)
  File "/usr/lib/python3.8/unittest/case.py", line 633, in _callTestMethod
    method()
  File "/opt/ros/noetic/lib/python3/dist-packages/rostest/runner.py", line 93, in fn
    self.fail(message)
  File "/usr/lib/python3.8/unittest/case.py", line 753, in fail
    raise self.failureException(msg)
--------------------------------------------------------------------------------
[Testcase: testt3390] ... FAILURE!
FAILURE: Package [fcsmap_fcs_suite_t3390] for test node [fcsmap_fcs_suite_t3390/node] does not exist
  File "/usr/lib/python3.8/unittest/case.py", line 60, in testPartExecutor
    yield
  File "/usr/lib/python3.8/unittest/case.py", line 676, in run
    self._callTestMethod(testMethod)
  File "/usr/lib/python3.8/unittest/case.py", line 633, in _callTestMethod
    method()
  File "/opt/ros/noetic/lib/python3/dist-packages/rostest/runner.py", line 93, in fn
    self.fail(message)
  File "/usr/lib/python3.8/unittest/case.py", line 753, in fail
    raise self.failureException(msg)
--------------------------------------------------------------------------------
[Testcase: testt3391] ... FAILURE!
FAILURE: Package [fcsmap_fcs_suite_t3391] for test node [fcsmap_fcs_suite_t3391/node] does not exist
  File "/usr/lib/python3.8/unittest/case.py", line 60, in testPartExecutor
    yield
  File "/usr/lib/python3.8/unittest/case.py", line 676, in run
    self._callTestMethod(testMethod)
  File "/usr/lib/python3.8/unittest/case.py", line 633, in _callTestMethod
    method()
  File "/opt/ros/noetic/lib/python3/dist-packages/rostest/runner.py", line 93, in fn
    self.fail(message)
  File "/usr/lib/python3.8/unittest/case.py", line 753, in fail
    raise self.failureException(msg)
--------------------------------------------------------------------------------
[Testcase: testt3392] ... FAILURE!
FAILURE: Package [fcsmap_fcs_suite_t3392] for test node [fcsmap_fcs_suite_t3392/node] does not exist
  File "/usr/lib/python3.8/unittest/case.py", line 60, in testPartExecutor
    yield
  File "/usr/lib/python3.8/unittest/case.py", line 676, in run
    self._callTestMethod(testMethod)
  File "/usr/lib/python3.8/unittest/case.py", line 633, in _callTestMethod
    method()
  File "/opt/ros/noetic/lib/python3/dist-packages/rostest/runner.py", line 93, in fn
    self.fail(message)
  File "/usr/lib/python3.8/unittest/case.py", line 753, in fail
    raise self.failureException(msg)
--------------------------------------------------------------------------------
[Testcase: testt3393] ... FAILURE!
FAILURE: Package [fcsmap_fcs_suite_t3393] for test node [fcsmap_fcs_suite_t3393/node] does not exist
  File "/usr/lib/python3.8/unittest/case.py", line 60, in testPartExecutor
    yield
  File "/usr/lib/python3.8/unittest/case.py", line 676, in run
    self._callTestMethod(testMethod)
  File "/usr/lib/python3.8/unittest/case.py", line 633, in _callTestMethod
    method()
  File "/opt/ros/noetic/lib/python3/dist-packages/rostest/runner.py", line 93, in fn
    self.fail(message)
  File "/usr/lib/python3.8/unittest/case.py", line 753, in fail
    raise self.failureException(msg)
--------------------------------------------------------------------------------
[Testcase: testt3394] ... FAILURE!
FAILURE: Package [fcsmap_fcs_suite_t3394] for test node [fcsmap_fcs_suite_t3394/node] does not exist
  File "/usr/lib/python3.8/unittest/case.py", line 60, in testPartExecutor
    yield
  File "/usr/lib/python3.8/unittest/case.py", line 676, in run
    self._callTestMethod(testMethod)
  File "/usr/lib/python3.8/unittest/case.py", line 633, in _callTestMethod
    method()
  File "/opt/ros/noetic/lib/python3/dist-packages/rostest/runner.py", line 93, in fn
    self.fail(message)
  File "/usr/lib/python3.8/unittest/case.py", line 753, in fail
    raise self.failureException(msg)
--------------------------------------------------------------------------------
[Testcase: testt3395] ... FAILURE!
FAILURE: Package [fcsmap_fcs_suite_t3395] for test node [fcsmap_fcs_suite_t3395/node] does not exist
  File "/usr/lib/python3.8/unittest/case.py", line 60, in testPartExecutor
    yield
  File "/usr/lib/python3.8/unittest/case.py", line 676, in run
    self._callTestMethod(testMethod)
  File "/usr/lib/python3.8/unittest/case.py", line 633, in _callTestMethod
    method()
  File "/opt/ros/noetic/lib/python3/dist-packages/rostest/runner.py", line 93, in fn
    self.fail(message)
  File "/usr/lib/python3.8/unittest/case.py", line 753, in fail
    raise self.failureException(msg)
--------------------------------------------------------------------------------
[Testcase: testt3396] ... FAILURE!
FAILURE: Package [fcsmap_fcs_suite_t3396] for test node [fcsmap_fcs_suite_t3396/node] does not exist
  File "/usr/lib/python3.8/unittest/case.py", line 60, in testPartExecutor
    yield
  File "/usr/lib/python3.8/unittest/case.py", line 676, in run
    self._callTestMethod(testMethod)
  File "/usr/lib/python3.8/unittest/case.py", line 633, in _callTestMethod
    method()
  File "/opt/ros/noetic/lib/python3/dist-packages/rostest/runner.py", line 93, in fn
    self.fail(message)
  File "/usr/lib/python3.8/unittest/case.py", line 753, in fail
    raise self.failureException(msg)
--------------------------------------------------------------------------------
[Testcase: testt3397] ... FAILURE!
FAILURE: Package [fcsmap_fcs_suite_t3397] for test node [fcsmap_fcs_suite_t3397/node] does not exist
  File "/usr/lib/python3.8/unittest/case.py", line 60, in testPartExecutor
    yield
  File "/usr/lib/python3.8/unittest/case.py", line 676, in run
    self._callTestMethod(testMethod)
  File "/usr/lib/python3.8/unittest/case.py", line 633, in _callTestMethod
    method()
  File "/opt/ros/noetic/lib/python3/dist-packages/rostest/runner.py", line 93, in fn
    self.fail(message)
  File "/usr/lib/python3.8/unittest/case.py", line 753, in fail
    raise self.failureException(msg)
--------------------------------------------------------------------------------
[Testcase: testt3398] ... FAILURE!
FAILURE: Package [fcsmap_fcs_suite_t3398] for test node [fcsmap_fcs_suite_t3398/node] does not exist
  File "/usr/lib/python3.8/unittest/case.py", line 60, in testPartExecutor
    yield
  File "/usr/lib/python3.8/unittest/case.py", line 676, in run
    self._callTestMethod(testMethod)
  File "/usr/lib/python3.8/unittest/case.py", line 633, in _callTestMethod
    method()
  File "/opt/ros/noetic/lib/python3/dist-packages/rostest/runner.py", line 93, in fn
    self.fail(message)
  File "/usr/lib/python3.8/unittest/case.py", line 753, in fail
    raise self.failureException(msg)
--------------------------------------------------------------------------------
[Testcase: testt3399] ... FAILURE!
FAILURE: Package [fcsmap_fcs_suite_t3399] for test node [fcsmap_fcs_suite_t3399/node] does not exist
  File "/usr/lib/python3.8/unittest/case.py", line 60, in testPartExecutor
    yield
  File "/usr/lib/python3.8/unittest/case.py", line 676, in run
    self._callTestMethod(testMethod)
  File "/usr/lib/python3.8/unittest/case.py", line 633, in _callTestMethod
    method()
  File "/opt/ros/noetic/lib/python3/dist-packages/rostest/runner.py", line 93, in fn
    self.fail(message)
  File "/usr/lib/python3.8/unittest/case.py", line 753, in fail
    raise self.failureException(msg)
--------------------------------------------------------------------------------

[ROSTEST]-----------------------------------------------------------------------

[testt3300][failed]
[testt3301][failed]
[testt3302][failed]
[testt3303][failed]
[testt3304][failed]
[testt3305][failed]
[testt3306][failed]
[testt3307][failed]
[testt3308][failed]
[testt3309][failed]
[testt3310][failed]
[testt3311][failed]
[testt3312][failed]
[testt3313][failed]
[testt3324][failed]
[testt3325][failed]
[testt3326][failed]
[testt3327][failed]
[testt3328][failed]
[testt3329][failed]
[testt3330][failed]
[testt3331][failed]
[testt3332][failed]
[testt3333][failed]
[testt3334][failed]
[testt3335][failed]
[testt3336][failed]
[testt3337][failed]
[testt3338][failed]
[testt3341][failed]
[testt3342][failed]
[testt3343][failed]
[testt3344][failed]
[testt3345][failed]
[testt3346][failed]
[testt3347][failed]
[testt3348][failed]
[testt3349][failed]
[testt3350][failed]
[testt3351][failed]
[testt3352][failed]
[testt3353][failed]
[testt3354][failed]
[testt3355][failed]
[testt3356][failed]
[testt3357][failed]
[testt3358][failed]
[testt3359][failed]
[testt3360][failed]
[testt3361][failed]
[testt3362][failed]
[testt3363][failed]
[testt3364][failed]
[testt3365][failed]
[testt3366][failed]
[testt3367][failed]
[testt3368][failed]
[testt3369][failed]
[testt3370][failed]
[testt3371][failed]
[testt3372][failed]
[testt3373][failed]
[testt3374][failed]
[testt3375][failed]
[testt3376][failed]
[testt3377][failed]
[testt3378][failed]
[testt3379][failed]
[testt3380][failed]
[testt3381][failed]
[testt3382][failed]
[testt3383][failed]
[testt3384][failed]
[testt3385][failed]
[testt3386][failed]
[testt3387][failed]
[testt3388][failed]
[testt3389][failed]
[testt3390][failed]
[testt3391][failed]
[testt3392][failed]
[testt3393][failed]
[testt3394][failed]
[testt3395][failed]
[testt3396][failed]
[testt3397][failed]
[testt3398][failed]
[testt3399][failed]

SUMMARY
 * RESULT: FAIL
 * TESTS: 0
 * ERRORS: 0
 * FAILURES: 88

ERROR: The following tests failed to run:
 * testt3300
 * testt3301
 * testt3302
 * testt3303
 * testt3304
 * testt3305
 * testt3306
 * testt3307
 * testt3308
 * testt3309
 * testt3310
 * testt3311
 * testt3312
 * testt3313
 * testt3324
 * testt3325
 * testt3326
 * testt3327
 * testt3328
 * testt3329
 * testt3330
 * testt3331
 * testt3332
 * testt3333
 * testt3334
 * testt3335
 * testt3336
 * testt3337
 * testt3338
 * testt3341
 * testt3342
 * testt3343
 * testt3344
 * testt3345
 * testt3346
 * testt3347
 * testt3348
 * testt3349
 * testt3350
 * testt3351
 * testt3352
 * testt3353
 * testt3354
 * testt3355
 * testt3356
 * testt3357
 * testt3358
 * testt3359
 * testt3360
 * testt3361
 * testt3362
 * testt3363
 * testt3364
 * testt3365
 * testt3366
 * testt3367
 * testt3368
 * testt3369
 * testt3370
 * testt3371
 * testt3372
 * testt3373
 * testt3374
 * testt3375
 * testt3376
 * testt3377
 * testt3378
 * testt3379
 * testt3380
 * testt3381
 * testt3382
 * testt3383
 * testt3384
 * testt3385
 * testt3386
 * testt3387
 * testt3388
 * testt3389
 * testt3390
 * testt3391
 * testt3392
 * testt3393
 * testt3394
 * testt3395
 * testt3396
 * testt3397
 * testt3398
 * testt3399

rostest log file is in /home/pedro/.ros/log/rostest-noetic-964176.log
