... logging to /home/pedro/.ros/log/rostest-noetic-969001.log
[ROSUNIT] Outputting test results to /home/pedro/.ros/test_results/fcsmap_fcs_suite/rostest-launch_fcsmap-3600-3699.xml
[Testcase: testt3600] ... FAILURE!
FAILURE: Package [fcsmap_fcs_suite_t3600] for test node [fcsmap_fcs_suite_t3600/node] does not exist
  File "/usr/lib/python3.8/unittest/case.py", line 60, in testPartExecutor
    yield
  File "/usr/lib/python3.8/unittest/case.py", line 676, in run
    self._callTestMethod(testMethod)
  File "/usr/lib/python3.8/unittest/case.py", line 633, in _callTestMethod
    method()
  File "/opt/ros/noetic/lib/python3/dist-packages/rostest/runner.py", line 93, in fn
    self.fail(message)
  File "/usr/lib/python3.8/unittest/case.py", line 753, in fail
    raise self.failureException(msg)
--------------------------------------------------------------------------------
[Testcase: testt3601] ... FAILURE!
FAILURE: Package [fcsmap_fcs_suite_t3601] for test node [fcsmap_fcs_suite_t3601/node] does not exist
  File "/usr/lib/python3.8/unittest/case.py", line 60, in testPartExecutor
    yield
  File "/usr/lib/python3.8/unittest/case.py", line 676, in run
    self._callTestMethod(testMethod)
  File "/usr/lib/python3.8/unittest/case.py", line 633, in _callTestMethod
    method()
  File "/opt/ros/noetic/lib/python3/dist-packages/rostest/runner.py", line 93, in fn
    self.fail(message)
  File "/usr/lib/python3.8/unittest/case.py", line 753, in fail
    raise self.failureException(msg)
--------------------------------------------------------------------------------
[Testcase: testt3602] ... FAILURE!
FAILURE: Package [fcsmap_fcs_suite_t3602] for test node [fcsmap_fcs_suite_t3602/node] does not exist
  File "/usr/lib/python3.8/unittest/case.py", line 60, in testPartExecutor
    yield
  File "/usr/lib/python3.8/unittest/case.py", line 676, in run
    self._callTestMethod(testMethod)
  File "/usr/lib/python3.8/unittest/case.py", line 633, in _callTestMethod
    method()
  File "/opt/ros/noetic/lib/python3/dist-packages/rostest/runner.py", line 93, in fn
    self.fail(message)
  File "/usr/lib/python3.8/unittest/case.py", line 753, in fail
    raise self.failureException(msg)
--------------------------------------------------------------------------------
[Testcase: testt3603] ... FAILURE!
FAILURE: Package [fcsmap_fcs_suite_t3603] for test node [fcsmap_fcs_suite_t3603/node] does not exist
  File "/usr/lib/python3.8/unittest/case.py", line 60, in testPartExecutor
    yield
  File "/usr/lib/python3.8/unittest/case.py", line 676, in run
    self._callTestMethod(testMethod)
  File "/usr/lib/python3.8/unittest/case.py", line 633, in _callTestMethod
    method()
  File "/opt/ros/noetic/lib/python3/dist-packages/rostest/runner.py", line 93, in fn
    self.fail(message)
  File "/usr/lib/python3.8/unittest/case.py", line 753, in fail
    raise self.failureException(msg)
--------------------------------------------------------------------------------
[Testcase: testt3604] ... FAILURE!
FAILURE: Package [fcsmap_fcs_suite_t3604] for test node [fcsmap_fcs_suite_t3604/node] does not exist
  File "/usr/lib/python3.8/unittest/case.py", line 60, in testPartExecutor
    yield
  File "/usr/lib/python3.8/unittest/case.py", line 676, in run
    self._callTestMethod(testMethod)
  File "/usr/lib/python3.8/unittest/case.py", line 633, in _callTestMethod
    method()
  File "/opt/ros/noetic/lib/python3/dist-packages/rostest/runner.py", line 93, in fn
    self.fail(message)
  File "/usr/lib/python3.8/unittest/case.py", line 753, in fail
    raise self.failureException(msg)
--------------------------------------------------------------------------------
[Testcase: testt3605] ... FAILURE!
FAILURE: Package [fcsmap_fcs_suite_t3605] for test node [fcsmap_fcs_suite_t3605/node] does not exist
  File "/usr/lib/python3.8/unittest/case.py", line 60, in testPartExecutor
    yield
  File "/usr/lib/python3.8/unittest/case.py", line 676, in run
    self._callTestMethod(testMethod)
  File "/usr/lib/python3.8/unittest/case.py", line 633, in _callTestMethod
    method()
  File "/opt/ros/noetic/lib/python3/dist-packages/rostest/runner.py", line 93, in fn
    self.fail(message)
  File "/usr/lib/python3.8/unittest/case.py", line 753, in fail
    raise self.failureException(msg)
--------------------------------------------------------------------------------

[ROSTEST]-----------------------------------------------------------------------

[testt3600][failed]
[testt3601][failed]
[testt3602][failed]
[testt3603][failed]
[testt3604][failed]
[testt3605][failed]

SUMMARY
 * RESULT: FAIL
 * TESTS: 0
 * ERRORS: 0
 * FAILURES: 6

ERROR: The following tests failed to run:
 * testt3600
 * testt3601
 * testt3602
 * testt3603
 * testt3604
 * testt3605

rostest log file is in /home/pedro/.ros/log/rostest-noetic-969001.log
